<mujoco model="6DoFArm">
    <compiler angle="degree"
            inertiafromgeom="true"
            texturedir="textures/"
            meshdir="mesh/visual/"/>
    <option timestep="2e-3"
            iterations="100"
            tolerance="1e-10"
            impratio="10"/>
    <!-- <size njmax="600" nconmax="150" nstack="300000"/> -->

    <default>
        <site rgba="0.8 0.6 0.7 0.3" type="ellipsoid" group="3"/>
        <!-- <geom contype='1' conaffinity='1' condim='4'  margin="1e-3" solref=".01 1" solimp=".99 .99 .01" /> -->
        <joint armature="0.01" damping=".1"/>
        <default class="UR5">
            <joint damping='.1'/>
        </default>
        <default class="UR5e">
            <joint damping='.1'/>
        </default>
        <default class="GRIPPER">
            <joint damping='.1'/>
        </default>
    </default>

    <visual>
        <map fogstart="3" fogend="5" znear="0.05"/>
        <quality shadowsize="2048"/>
        <scale framelength="0.1"
            framewidth="0.005"
            contactwidth="0.1"
            contactheight="0.005"
            forcewidth="0.01"
            />
    </visual>

    <!--Assets-->
    <asset>
        <mesh name="bracket"        file="bracket.STL"  scale="0.0022 0.002 0.002"/>
        <mesh name="bracket2"        file="bracket.STL"  scale="0.001 0.001 0.001"/>
        <mesh name="servo"        file="servo_motor.stl"  scale="0.002 0.0025 0.002"/>

        <!--Textures-->
         <texture name="ur5_tex"     type="2d"       builtin="flat" height="32" width="32" rgb1="0.45 0.45 0.45" />
        <texture name="bench_tex"   type="2d"       builtin="flat" height="32" width="32" rgb1="0.7 0.7 0.7" /> -->
        <texture name="sky_tex"     type="skybox"   builtin="gradient" width="100" height="100" rgb1="1 1 1" rgb2="0.3 0.3 0.8" />
        <texture name="floor_tex"   type="2d"        builtin="checker" rgb1=".2 .3 .4" rgb2=".1 .2 .3" width="100" height="100" />
       <texture name="wood"        type="cube"     file="wood2.png"/> 
        <texture name="metal"        type="cube"     file="metal2.png"/> 
        <!--Materials-->
        <material name="ur5_mat"        texture="ur5_tex"   shininess="0.9" specular="0.75" reflectance="0.3"/>
        <material name='floor_mat'      texture="floor_tex"  shininess="0.8" texrepeat="10 10" specular="0.7"  reflectance="0.5" />
        <material name="bench_mat"      texture="metal"   shininess="0.1" specular="0.5" reflectance="0.2"/>
        <material name="tablecube"      texture="wood" rgba=".8 .8 .8 1"/>
    </asset>

    <!--Contacts-->
    

    <!--MODEL DESCRIPTION-->
    <worldbody>
        <!--Lighting parameters-->
        <light name="light3" mode="targetbody" target="box_link" directional="true" pos="1 1 3" />
        <!--Floor Property-->
        <geom name='floor' material="floor_mat" pos='0 0 0' size='2.5 2.5 0.1'  type='plane' />

        <body name="box_link" pos="0 0 0">
                <geom name="Box" size="0.15 0.15 0.1" pos="0 0 0.1" type="box" material="tablecube" friction = "0 0 0"/>
                        <body>
                            <geom type="mesh"  mesh="bracket" material="ur5_mat" pos = "-0.05 0.045 0.2" euler = "90 0 0" mass = "0.01" />
                            <body>
                                <geom name = "yservo"  type="mesh" mesh="servo" material="ur5_mat" pos="-0.045 -0.001 .3675" euler = "0 -180 90" mass = "0.5" />
                                <joint name="pr1" type="hinge" pos = "0.03 0.0179 .2935" axis = "1 0 0" limited="true" range = "-90 90"/>
                                <body>
                                <geom type="mesh"  mesh="bracket" material="ur5_mat" pos = "-0.03 -0.0375 .375" euler = "90 90 0"/>
                                <body>
                                    <geom name = "xservo" type="mesh" mesh="servo" material="ur5_mat" pos="-0.022 0.075 .54225" euler = "0 180 180" mass = "0.5"     />
                                    <joint name="pr2" type="hinge" pos = "-0.003 -0.02 .4685" axis = "0 -1 0" limited="true" range = "-135 135"/>
                                    <camera name = "endcam" pos = "0.006 0.13 -0.899"/>
                                </body>
                            </body>
                            </body>   
                        </body>
        </body>
    </worldbody>


    <actuator>
        <motor name="arm_joint" ctrllimited="true" ctrlrange="-0.01 0.01" joint="pr1" gear="101"/>
        <motor name="wrist_joint" ctrllimited="true" ctrlrange="-0.01 0.01" joint="pr2" gear="101"/>
    </actuator>
    </mujoco>